<?xml version="1.0"?>
<!-- Xacro file description-->
<robot name="myrobot" xmlns:xacro="http://www.ros.org/wiki/xacro" >

    <!-- dummy link-->
    <link name="robot_footprint"/> 
    
    <!-- chassis link-->
    <link name="chassis">
        <inertial>
            <origin xyz="0.0 0.0 0.0" />
            <mass value="5"/>
            <inertia ixx="0.1" ixy="0.0" ixz="0.0" iyy="0.1" iyz="0.0" izz="0.1"/>
        </inertial>
        <visual>
            <origin xyz="0.0 0.0 0.2" />
            <geometry>
                <box size="0.6 0.46 0.2"/>
            </geometry>
            <material name="Red">
                <color rgba="1.0 0.0 0.0 1.0"/>
            </material>
        </visual>
        <collision>
            <origin xyz="0.0 0.0 0.2" />
            <geometry>
                <box size="0.6 0.46 0.2"/>
            </geometry>
            <material name="Red">
                <color rgba="1.0 0.0 0.0 1.0"/>
            </material>
        </collision>
    
    </link>
    <joint name="joint_chassis" type="fixed">
        <parent link="robot_footprint"/>
        <child link="chassis"/>
    </joint>
    
    <!-- Front left wheel link-->
    <link name="front_left_wheel">
        <inertial>
            <origin xyz="0.0 0.0 0.0" rpy="0.0 0.0 0.0"/>
            <mass value="1.1"/>
            <inertia ixx="0.1" ixy="0.0" ixz="0.0" iyy="0.1" iyz="0.0" izz="0.1"/>
        </inertial>
        <visual name="front_left_wheel_visual">
            <origin xyz="0.0 0.0 0.0" rpy="0 1.5707 1.5707"/>
            <geometry>
                <cylinder radius="0.096" length="0.0498"/>
             </geometry>
             <material name="Black">
                <color rgba="0.0 0.0 0.0 1.0"/>
            </material>
        </visual>
        <collision name="front_left_wheel_collision">
            <origin xyz="0.0 0.0 0.0" rpy="0 1.5707 1.5707"/>
            <geometry>
                <cylinder radius="0.096" length="0.0498"/>
            </geometry>
            <material name="Black">
                <color rgba="0.0 0.0 0.0 1.0"/>
            </material>
        </collision>
    </link>
    <joint name="joint_front_left_wheel" type="continuous">
        <origin xyz="0.175 0.25 0.1" rpy="0.0 0.0 0.0"/>
        <parent link="chassis"/>
        <child link="front_left_wheel"/>
        <axis xyz="0 1 0" rpy="0 0 0"/>
        <limit effort="10000" velocity="1000" />
	    <dynamics damping="1.0" friction="1.0" />
    </joint>
       
    <!-- back left wheel link-->
    <link name="back_left_wheel">
        <inertial>
            <origin xyz="0.0 0.0 0.0" rpy="0.0 0.0 0.0"/>
            <mass value="1.1"/>
            <inertia ixx="0.1" ixy="0.0" ixz="0.0" iyy="0.1" iyz="0.0" izz="0.1"/>
        </inertial>
        <visual name="back_left_wheel_visual">
            <origin xyz="0.0 0.0 0.0" rpy="0 1.5707 1.5707"/>
            <geometry>
                <cylinder radius="0.096" length="0.0498"/>
            </geometry>
            <material name="Black">
                <color rgba="0.0 0.0 0.0 1.0"/>
            </material>
        </visual>
        <collision name="back_left_wheel_collision">
            <origin xyz="0.0 0.0 0.0" rpy="0 1.5707 1.5707"/>
            <geometry>
                <cylinder radius="0.096" length="0.0498"/>
            </geometry>
            <material name="Black">
                <color rgba="0.0 0.0 0.0 1.0"/>
            </material>
        </collision>
    </link>
    <joint name="joint_back_left_wheel" type="continuous">
        <origin xyz="-0.175 0.25 0.1" rpy="0.0 0.0 0.0"/>
        <parent link="chassis"/>
        <child link="back_left_wheel"/>
        <axis xyz="0 1 0" rpy="0 0 0"/>
        <limit effort="10000" velocity="1000" />
	    <dynamics damping="1.0" friction="1.0" />
    </joint>
    
    <!-- front right wheel link-->
    <link name="front_right_wheel">
        <inertial>
            <origin xyz="0.0 0.0 0.0" rpy="0.0 0.0 0.0"/>
            <mass value="1.1"/>
            <inertia ixx="0.1" ixy="0.0" ixz="0.0" iyy="0.1" iyz="0.0" izz="0.1"/>
        </inertial>
        <visual name="front_right_wheel_visual">
            <origin xyz="0.0 0.0 0.0" rpy="0 1.5707 1.5707"/>
            <geometry>
                <cylinder radius="0.096" length="0.0498"/>
            </geometry>
            <material name="Black">
                <color rgba="0.0 0.0 0.0 1.0"/>
            </material>
        </visual>
        <collision name="front_right_wheel_collision">
            <origin xyz="0.0 0.0 0.0" rpy="0 1.5707 1.5707"/>
            <geometry>
                <cylinder radius="0.096" length="0.0498"/>
            </geometry>
            <material name="Black">
                <color rgba="0.0 0.0 0.0 1.0"/>
            </material>
        </collision>
    </link>
    <joint name="joint_front_right_wheel" type="continuous">
        <origin xyz="0.175 -0.25 0.1" rpy="0.0 0.0 0.0"/>
        <parent link="chassis"/>
        <child link="front_right_wheel"/>
        <axis xyz="0 1 0" rpy="0 0 0"/>
        <limit effort="10000" velocity="1000" />
	    <dynamics damping="1.0" friction="1.0" />
    </joint>
    <!-- back right wheel link-->
    <link name="back_right_wheel">
        <inertial>
            <origin xyz="0.0 0.0 0.0" rpy="0.0 0.0 0.0"/>
            <mass value="1.1"/>
            <inertia ixx="0.1" ixy="0.0" ixz="0.0" iyy="0.1" iyz="0.0" izz="0.1"/>
        </inertial>
        <visual name="back_right_wheel_visual">
            <origin xyz="0.0 0.0 0.0" rpy="0 1.5707 1.5707"/>
            <geometry>
                <cylinder radius="0.096" length="0.0498"/>
            </geometry>
            <material name="Black">
                <color rgba="0.0 0.0 0.0 1.0"/>
            </material>
        </visual>
        <collision name="back_right_wheel_collision">
            <origin xyz="0.0 0.0 0.0" rpy="0 1.5707 1.5707"/>
            <geometry>
                <cylinder radius="0.096" length="0.0498"/>
            </geometry>
            <material name="Black">
                <color rgba="0.0 0.0 0.0 1.0"/>
            </material>
        </collision>
    </link>
    <joint name="joint_back_right_wheel" type="continuous">
        <origin xyz="-0.175 -0.25 0.1" rpy="0.0 0.0 0.0"/>
        <parent link="chassis"/>
        <child link="back_right_wheel"/>
        <axis xyz="0 1 0" rpy="0 0 0"/>
        <limit effort="10000" velocity="1000" />
	    <dynamics damping="1.0" friction="1.0" />
    </joint>
    
    <!-- lidar link-->
    
    <link name="sensor">
        <inertial>
            <origin xyz="0 0 0" rpy="0 0 0"/>
            <mass value="0.9"/>
            <inertia ixx="1.0" ixy="0.0" ixz="0.0" iyy="1.0" iyz="0.0" izz="1.0"/>
        </inertial>
        <visual>
            <origin xyz="0 0 0" rpy="0 0 0"/>
            <geometry>
                <cylinder radius="0.1" length="0.05"/>
            </geometry>
            <material name="Green">
                <color rgba="0.0 1.0 0.0 1.0"/>
            </material>
        </visual>
        <collision>
            <origin xyz="0 0 0" rpy="0 0 0"/>
            <geometry>
                <cylinder radius="0.1" length="0.05"/>
            </geometry>
            <material name="Green">
                <color rgba="0.0 1.0 0.0 1.0"/>
            </material>
        </collision>
    </link>
    <joint name="sensor_joint" type="fixed">
        <origin xyz="0.0 0.0 0.304" rpy="0 0 0"/>
        <parent link="chassis"/>
        <child link="sensor"/>
        <axis xyz="0 0 0"/>
    </joint>
    
    <!-- Color of bot -->
    
    <gazebo reference="chassis">
		<material>Gazebo/Red</material>
	</gazebo>

    <gazebo reference="sensor">
        <material>Gazebo/Green</material>
    </gazebo>
    
    <gazebo reference="front_left_wheel">
		<material>Gazebo/Black</material>
		<kp>1000000.0</kp> <!-- kp and kd for rubber -->
		<kd>100.0</kd>
		<mu1>1.0</mu1>
		<mu2>1.0</mu2>
		<maxVel>1.0</maxVel>
		<minDepth>0.00</minDepth>
	</gazebo>
    
    <gazebo reference="back_left_wheel">
		<material>Gazebo/Black</material>
		<kp>1000000.0</kp> <!-- kp and kd for rubber -->
		<kd>100.0</kd>
		<mu1>1.0</mu1>
		<mu2>1.0</mu2>
		<maxVel>1.0</maxVel>
		<minDepth>0.00</minDepth>
	</gazebo>
    
    <gazebo reference="front_right_wheel">
		<material>Gazebo/Black</material>
		<kp>1000000.0</kp> <!-- kp and kd for rubber -->
		<kd>100.0</kd>
		<mu1>1.0</mu1>
		<mu2>1.0</mu2>
		<maxVel>1.0</maxVel>
		<minDepth>0.00</minDepth>
	</gazebo>
    
    <gazebo reference="back_right_wheel">
		<material>Gazebo/Black</material>
		<kp>1000000.0</kp> <!-- kp and kd for rubber -->
		<kd>100.0</kd>
		<mu1>1.0</mu1>
		<mu2>1.0</mu2>
		<maxVel>1.0</maxVel>
		<minDepth>0.00</minDepth>
	</gazebo>
</robot>